Workbook

Sheet To Do List
A1: Task | B1: Due Date | C1: Priority | D1: Status | E1: Notes
A2: Pre marital teaching | B2: TBC | C2: High | D2: Not Started | E2: I will ask one of our leader to have a series of session with us. I already have the book and note we will be going through. I will also share your details with him if that's okay with you. As mentioned. I want to be the best husban for you. So what I usually do is that i go for coffe chat with some good model (man) for councilling. Once we are here we can decide to see one or two couple and you will decide who you like the most. Kindly confirm if you would like your pastor to bless us. If that's the case. he should tell you what is required from his side; teaching? book to read? or task to be done.
A3: Prayer Altar | B3: TBC | C3: High | D3: Not Started | E3: Key thing to pray for: - Blood line, ties for family or people, our wedding, our marriage, our love, our understanding, our children, our plan on when to have them, our finances, our home (I want us to buy a house), our businesses, our spirituallity , our mindset. (Please add stuff as the spirit will lead you)
A4: Doctor appointment | B4: End of September | C4: Low | D4: Not Started | E4: Kindly ask your father what we need to do for this. Any recommendation of a place we can go. Or if we will do it here. But let him feel invole (as he is a doctor)
A5: House hold/ monthly expenses | B5: End of August | C5: Medium | D5: Not Started
A6: Have a dinner/supper with your tantine | B6: End of August | C6: Medium | D6: Not Started | E6: Once you know when you are coming, kindly ask if we can have supper toguether at her place, as you would like her to know me. Let us have some suggestion of date
A7: Photoshoot | B7: End of August | C7: Low | D7: Not Started | E7: Please confirm
A8: Dinner with Namia | C8: Medium | D8: In Progress | E8: Matt to book a restaurant in sea point
A9: Cinema/ outing | C9: Medium | E9: Movie suggestion: odyssey (please check if you will be interrested) :D
B10: END OF DECEMBER | C10: High | D10: In Progress | E10: :D
A11: Get Marriage license | B11: TBD | C11: High | D11: Not Started
A12: Matt flight Tickets for sep | B12: 24/09/2026 | C12: High | D12: Not Started | E12: we shouldn't forget to book tickets for your trip to Durban in September

Sheet Wedding Expenses
A1: Item | B1: Budget | C1: Actual | D1: Paid? | E1: Notes | G1: Total Budget | H1: Total Actual
A2: Salle de fete | B2: 45000 | G2: =SUM(B2:B201) -> 167500 | H2: =SUM(C2:C201) -> 0
A3: Food (with salle de fete?) | B3: 50000
A4: Photo & Video | B4: 25000
A5: Clothes
A6: Travelling | B6: 6000+
A7: Transport pour les marriE
A8: Airbnb
A9: Transport | B9: 6000
A10: Music
A11: bridesmaid & groomsmen
A12: Decor | B12: 10000
A13: tailor
A14: Clothing fabric
A15: Drinks and beverages | B15: 3000
A16: Bridal jewelry &accessories
A17: Groom's jewelry & Accessories
A18: Wedding Rings | B18: 8000
A19: honeymoon | B19: 17500
A20: invitation cards
A21: wedding cake | B21: 3000

Sheet Sheet2
A2: 1. White Box
A3: Venue | B3: Food/per | C3: Decor | D3: Drink | E3: Number | G3: Total
A4: 43500 | B4: 250 | C4: 80000 | D4: 50 | E4: 200 | G4: =A4+C4+(B4*E4)+(D4*E4) -> 183500
G5: =A5+C5+(B5*E5)+(D5*E5) -> 0
A6: 2.Collisheen Estate
A7: Venue | B7: Food/per | C7: Decor | D7: Drink | E7: Number
A8: 43000 | B8: 350 | C8: 80000 | D8: 50 | E8: 200 | G8: =A8+C8+(B8*E8)+(D8*E8) -> 203000
A9: Venue | B9: Food/per | C9: Decor | D9: Drink | E9: Number
A10: 3. Sharula Estate
A11: 86000 | B11: 250 | C11: 80000 | D11: 50 | E11: 200 | G11: =A11+C11+(B11*E11)+(D11*E11) -> 226000
A12: 4
A13: Venue | B13: Food/per | C13: Decor | D13: Drink | E13: Number
A14: Extra cost Backup=R750 Bar (just the space) = R3K Garden=R3k | G14: =A14+C14+(B14*E14)+(D14*E14) -> #VALUE!
G15: =A15+C15+(B15*E15)+(D15*E15) -> 0
A16: 4.Blue Waters Hotel
A17: Venue | B17: Food/per | C17: Decor | D17: Drink | E17: Number
A18: 725 | B18: 0 | C18: 0 | D18: 0 | E18: 150 | G18: =(A18*E18)+C18+(B18*E18)+(D18*E18) -> 108750
A19: Add on= R10k
A21: 5 Mount Edgecombe
A22: Venue | B22: Food/per | C22: Decor | D22: Drink | E22: Number
A23: 90800 | B23: 350 | C23: 0 | D23: 50 | E23: 200 | G23: =A23+C23+(B23*E23)+(D23*E23) -> 170800

Sheet Household Expenses
A1: Category | B1: Budget | C1: Actual | D1: Date | E1: Notes | G1: Total Budget | H1: Total Actual
A2: Sofa | E2: Please give me 3 Options | G2: =SUM(B2:B202) -> 171500 | H2: =SUM(C2:C202) -> 0
A3: Bed (double or Queen?) | E3: TBC (depending on room size
A4: Living room
A5: Couch | B5: 20000
A6: table | B6: 2000
A7: living room decor | B7: 450
A8: living room rug | B8: 3000
A9: heater | B9: 1500
A10: Curtains | B10: 1000
A11: dining room
A12: dining set | B12: 11000
A13: dining room decor
A15: kitchen
A16: microwave | B16: 1400
A17: cutlery | B17: 600
A18: plates | B18: 1300
A19: mugs/glasses | B19: 600
A20: kitchen decor
A21: pots/pans | B21: 2600
A22: kettle | B22: 1000
A23: toaster | B23: 600
A24: waffle make | B24: 300
A25: airfryer | B25: 1500
A26: oven baking set
A28: bedroom
A29: bed ( queen | B29: 9000
A30: bedsheets /blankets | B30: 2000
A31: pillows and throws | B31: 1500
A32: headboard set | B32: 2000
A33: bedroom decor
A34: lamps | B34: 1000
A35: bedroom rug | B35: 3000
A36: electric duvet | B36: 400
A38: bathroom
A39: bathroom set | B39: 500
B41: =SUM(B2:B39) -> 68250
A42: Monthly expenses
A43: Rent | B43: 10000
A44: petrol | B44: 1200
...

Sheet Sheet1
B1: FAMILLE PATERNELLE
B3: Deux ensembles Costume 3 pièces Complet prêt à porter (taille 56) + une Chemise manche longue (XXL) et une Cravate assortie | C3: 3600 | D3: 2 | E3: =C3*D3 -> 7200 | F3: 0 | H3: V
B4: Une paire de Chaussure homme (pointure 44) | C4: 2500 | D4: 1 | E4: =C4*D4 -> 2500 | F4: 0 | H4: V
B5: Une Montre – homme/GUESS GC CHRONOGRAPHE | C5: 13000 | D5: 1 | E5: =C5*D5 -> 13000 | F5: 0 | H5: Do
B6: Une Couverture en laine | C6: 2000 | D6: 1 | E6: =C6*D6 -> 2000 | F6: 0 | G6: 160 | H6: A
B7: Trois pièces Super WAX Hollandais | C7: 2600 | D7: 3 | E7: =C7*D7 -> 7800 | F7: 0 | H7: H=600$
B8: Un sac de Sel (25 kg) | C8: 500 | D8: 1 | E8: =C8*D8 -> 500 | F8: =C8*D8 -> 500 | H8: Da
B9: Une Dame-jeanne de Vin rouge (5 litres) | C9: 1000 | D9: 1 | E9: =C9*D9 -> 1000 | F9: =C9*D9 -> 1000 | G9: 15 | H9: M
B10: Une Chèvre | C10: 3500 | D10: 1 | E10: =C10*D10 -> 3500 | F10: 0 | H10: Do
B11: Une Machette TRAMOTINA | C11: 200 | D11: 1 | E11: =C11*D11 -> 200 | F11: =C11*D11 -> 200 | H11: Da
B12: Boissons : 4 bouteilles de whisky Jack Daniels (Grand Format) + 20 packs (de 12) de bières + 20 packs (de 12) de boissons sucrées | C12: =2000+8000+2800 -> 12800 | D12: 1 | E12: =C12*D12 -> 12800 | F12: =C12*D12 -> 12800 | H12: MM
B13: Dot (en espèces) : 3.000 USD | C13: 49000 | D13: 1 | E13: =C13*D13 -> 49000 | F13: =C13*D13 -> 49000 | H13: MM
E14: =SUM(E3:E13) -> 99500 | F14: =C14*D14 -> 0
E15: =C15*D15 -> 0 | F15: =C15*D15 -> 0
B16: FAMILLE MATERNELLE | E16: =C16*D16 -> 0 | F16: =C16*D16 -> 0
E17: =C17*D17 -> 0 | F17: =C17*D17 -> 0
B18: Deux pièces Super Wax + Deux foulards de tête (Guess) | C18: =2600+750 -> 3350 | D18: 2 | E18: =C18*D18 -> 6700 | F18: 0 | H18: H+Ma+
B19: Deux paires de Chaussures Dame (pointure 40) | C19: 1000 | D19: 2 | E19: =C19*D19 -> 2000 | F19: 0 | H19: Mi
B20: Un Sac à main (Guess) | C20: 3000 | D20: 1 | E20: =C20*D20 -> 3000 | F20: 0 | H20: Do
B21: Une Montre Dame (Guess) | C21: 4000 | D21: 1 | E21: =C21*D21 -> 4000 | F21: 0 | H21: Do
B22:  Un ensemble costume 3 pièces (taille 48 Europe/38 USA) | C22: 3600 | D22: 1 | E22: =C22*D22 -> 3600 | F22: 0 | H22: V
B23:  Une paire de chaussure homme (pointure 40) | C23: 2500 | D23: 1 | E23: =C23*D23 -> 2500 | F23: 0 | H23: V
B24:  Une grande Marmite inox (Ma Famille) | C24: 750 | D24: 1 | E24: =C24*D24 -> 750 | F24: 0 | H24: Da
B25:  Une grande bassine (Libala bosembo) | C25: 200 | D25: 1 | E25: =C25*D25 -> 200 | F25: 0 | H25: Da
B26:  20 Litres d’huile végétale | C26: 900 | D26: 1 | E26: =C26*D26 -> 900 | F26: 0 | H26: Da
B27:  5 kg de Sel | C27: 500 | D27: 1 | E27: =C27*D27 -> 500 | F27: 0 | H27: Da
B28:  Une boîte de lait (grand format) | C28: 800 | D28: 1 | E28: =C28*D28 -> 800 | F28: 0 | H28: Da
B29:  10 kg de sucre | C29: 300 | D29: 1 | E29: =C29*D29 -> 300 | F29: 0 | H29: Da
B30:  Dot (en espèce) : 700 USD | C30: 11500 | D30: 1 | E30: =C30*D30 -> 11500 | F30: =C30*D30 -> 11500 | H30: MM
E31: =SUM(E18:E30) -> 36750
E32: =C32*D32 -> 0
E33: =C33+D33 -> 0
E34: =E14+E31 -> 136250 | F34: =sum(F4:F33) -> 75000
E35: =C35+D35 -> 0
E36: =E34*0.063 -> 8583.75 | F36: =F34*0.063 -> 4725

Sheet Dashboard
A1: Expense Dashboard
A3: Wedding Budget | B3: ='Wedding Expenses'!G2 -> 167500
A4: Wedding Actual | B4: ='Wedding Expenses'!H2 -> 0
A6: Household Budget | B6: ='Household Expenses'!G2 -> 171500
A7: Household Actual | B7: ='Household Expenses'!H2 -> 0

Sheet List dinvite MM
A2: Family
A3: Name | B3: Number | C3: Reality | D3: Confirmed
A4: Helene | B4: 2 | C4: 1 | D4: Y
A5: Veronique | B5: 4 | C5: 4 | D5: 2 confirmed
A6: Dieudonne | B6: 1 | C6: 1 | D6: Y
A7: Mirielle | B7: 2 | C7: 2 | D7: Y
A8: Arlette | B8: 3 | C8: 2 | D8: Y
A9: Daniel | B9: 6 | C9: 6 | D9: Y
A10: Eric | B10: 2 | C10: 2 | D10: Y
A11: Thierry | B11: 2 | C11: 2 | D11: Y
A12: Henri & Muclare | B12: 2 | C12: 2 | D12: Y
B13: =sum(B4:B12) -> 24 | C13: =sum(C4:C12) -> 22
A15: Toton Placide Kabala | B15: 2 | C15: 2
A16: Senior Kabala | B16: 2 | C16: 1
A17: Mirielle Banza | B17: 2 | C17: 2
A18: Tantine Dianda | B18: 3 | C18: 3
A19: Tonton Aidevous | B19: 2 | C19: 2
A20: Sophie | B20: 4 | C20: 2
A21: Pathy | B21: 2 | C21: 1
A22: Felix & Doris | B22: 4 | C22: 1
B23: =sum(B14:B22) -> 21 | C23: =sum(C14:C22) -> 14
A24: Friend
A25: Nic-Land Kolela | B25: 1 | C25: 1
A26: Dieudonne Byabene | B26: 2 | C26: 2
A27: Ephraim Kalonji | B27: 2 | C27: 2
A28: Leon Chenge | B28: 2 | C28: 2
A29: Esther Chishibanji | B29: 1 | C29: 1
A30: Catherine Namayega | B30: 1 | C30: 1
A31: Sophia M'zimbes | B31: 1 | C31: 1
A32: Elie Wasa | B32: 2 | C32: 1
A33: Kevin Ejiba | B33: 2 | C33: 1
B34: =sum(B24:B33) -> 14 | C34: =sum(C24:C33) -> 12
A35: Church
A36: Humphrey Bande | B36: 2 | C36: 2
A37: Joelle & Joshua | B37: 2 | C37: 2
A38: Beks | B38: 1 | C38: 0 | D38: N
A39: Councilia | B39: 2 | C39: 2
A40: Joshua & Debrorah Matesun | B40: 3 | C40: 1
A41: Domingo | B41: 2 | C41: 1
A42: Julie-Ann | B42: 2 | C42: 2
...

Sheet Guest List Nana 
A1: Family (Mom Side)
A2: Name | B2: Number | C2: Reality | D2: confirmed
A3: Pepe Medar Kabamba | B3: 1
A4: Meme Agnes Ntumba | B4: 1
A5: Ghyslain Kabamba | B5: 2
A6: Yolande Ntambwe | B6: 3
A7: Cynthia Kabamba | B7: 1
A8: Gloria Kabamba | B8: 1
A9: Claudine and Max Makelele | B9: 2
A10: Lydie Meta Mundele | B10: 1
B11: 2
A12: Gedeon Buka | B12: 1
A13: Papa Theo | B13: 2
A14: Papa Jean-Marie | B14: 2
A15: Frida | B15: 2
A16: Alda | B16: 2
B17: =SUM(B3:B16) -> 23
A19: Family(Dad's Side)
A20: Daniel and Josephine Mundele | B20: 4
A21: Dad | B21: 1
A22: Ginette Mundele | B22: 3
A23: Maman Chantal Mundele | B23: 1
A24: Maman Cisco | B24: 1
A25: Nanamichele Shabani | B25: 2
A26: Jean-Paul et Sylvie Debruyne
B27: =SUM(B20:B26) -> 12
A28: Family Friends
A29: Cyril & Belata Kiyoyo | B29: 2
A30: Cyril & Ivette Mandombe | B30: 2
A31: Ephrem & Cathy Kabala | B31: 2
A32: Albert and Benita Mbelu | B32: 2
A33: Jimmy & Mado Amsini | B33: 2
A34: Couple Holen | B34: 2
A35: Sandra et Junior LUPEMBA | B35: 2
A36: Freddy & Liliane Kabambi | B36: 2
B37: 2
A38: Fonteine & Anguy Munkungapyo | B38: 2
A39: Justine & Junior Kondjo | B39: 2
A40: Bruno and Lucette Kalala | B40: 2
A41: Maître Laurent & Madame Yvonne Lukoji | B41: 2
...

Sheet Sheet5
A1: Category / Task | B1: Estimated Cost (R) | C1: Estimated Cost (USD) | D1: Assigned Family / Person | E1: Payment / Status | F1: Notes | H1: Maloba | I1: Mundele | J1: Couple
A2: Venue/ Church/ ceremony | B2: 45400 | C2: $5 772 | D2: Maloba | E2: Not paid | H2: =B2+B9+B10+B11+B12 -> 80400 | I2: =B3+B5+B6+B13+B14+B16 -> 115400 | J2: =B4+B7+B15 -> 9000
A3: Decoration | B3: 45400 | D3: Mundele
A4: Breakage deposit | B4: 2000 | C4: 123 | D4: Couple | E4: Not paid
A5: Main catering – 200 guests | B5: 40000 | C5: $3 077 | D5: Mundele | E5: To agree
A6: Post-church refreshments – 200 guests | B6: 10000 | C6: 923 | D6: Mundele | E6: To agree
A7: Serving staff/protocol (transport) | B7: 1000 | C7: 615 | D7: Couple | E7: To agree
A8: Day-of coordinator | B8: 0 | C8: 492 | D8: Family to be assigned | E8: To agree
A9: MC | B9: 5000 | C9: 308 | D9: Maloba | E9: To agree
A10: DJ + sound system | B10: 10000 | C10: 615 | D10: Maloba | E10: To agree
A11: Photography | B11: 10000 | C11: 738 | D11: Maloba | E11: To agree
A12: Videography | B12: 10000 | C12: 738 | D12: Maloba | E12: To agree
A13: Wedding cake | B13: 6000 | C13: 369 | D13: Mundele | E13: To agree
A14: Drinks (water, juice,2 champagne/10, cold drinks | B14: 10000 | C14: 492 | D14: Mundele | E14: To agree
A15: Guest favour/ gift– 200 | B15: 6000 | C15: 308 | D15: Couple | E15: To agree
A16: Invitations / programmes / signage | B16: 4000 | C16: 246 | D16: Mundele | E16: To agree
A17: Additional floral/decor requirements | B17: 0 | C17: 308 | D17: Family to be assigned | E17: Only if required
A18: Transport / logistics | B18: 0 | C18: 308 | D18: Family to be assigned | E18: If agreed
A19: Contingency (not included yet) | B19: R10 000 | C19: 615 | D19: Shared | E19: Reserve
A20: TOTAL WORKING BUDGET | B20: =H2+I2+J2 -> 204800 | C20: $16 047
C22: $10 152
A26: INDIVIDUAL FAMILY / PERSONAL COSTS
A27: Family / Person | B27: Responsibility | C27: Estimated Cost (R) | D27: Estimated Cost (USD) | E27: Paid | F27: Balance
A28: Bride's family | B28: Bride price / traditional contribution | C28: R162 500 | D28: $10 000 | E28: No | F28: R162 500
A29: Bride's family | B29: Bride's dress & accessories | E29: No
A30: Bride's family | B30: Bridesmaids' dresses | E30: No
A31: Groom's family | B31: Groom's traditional requirements | E31: No
A32: Groom's family | B32: Groomsmen's attire | E32: No
A33: To be assigned | B33: Other agreed family responsibility | E33: No
A35: USD/ZAR planning rate used: $1 = R16.25 (15 September 2026)

Sheet Sheet6
A1: LIST OF GIFTS | B1: Estimated Cost | C1: Amount Cobtributed
A2: Home And furniture
A3: Sofa/Couch | B3: 35000
A4: Coffee Table
A5: TV Stand | B5: 3000
A6: Dining Table | B6: 4000
A7: Dining Chairs | B7: 2800
A8: Bookshelf | B8: 2200
A9: Full-Length Mirror | B9: 800
A10: Floor Lamp | B10: 1500
A12: Kitchen appliances/Dining
A13: Fridge/Freezer | B13: 12000
A14: Microwave | B14: 3500
A15: Air Fryer | B15: 3000
A16: Blender | B16: 749
A17: Food Processor | B17: 1000
A18: Electric Kettle | B18: 1500
A19: Toaster | B19: 500
A20: Sandwich Maker | B20: 700
A21: Coffee Machine
A22: Slow Cooker | B22: 1000
A23: Rice Cooker | B23: 800
A24: Pressure Cooker | B24: 1299
A25: Hand Mixer
A26: Stand Mixer
A27: Juicer | B27: 1600
A28: Kitchen Scale | B28: 400
A29: Water Filter/Purifier | B29: 2000
A30: Dinner Plate Set | B30: 1250
A31: Side Plate Set | B31: 600
A32: Bowl Set | B32: 600
A33: Cutlery Set | B33: 800
A34: Drinking Glasses | B34: 500
A35: Wine Glasses | B35: 600
A36: Coffee Mugs | B36: 400
A37: Serving Platters | B37: 500
A38: Serving Bowls | B38: 400
... A49: Dish Rack | B49: 400
A51: Laundry
A52: Washing Machine | B52: 9000
...
